Workbook
Name r_n: Reviews!$A$2:$A$501
Name r_date: Reviews!$B$2:$B$501
Name r_month: Reviews!$C$2:$C$501
Name r_star: Reviews!$D$2:$D$501
Name r_ver: Reviews!$E$2:$E$501
Name r_primary: Reviews!$H$2:$H$501
Name r_sub: Reviews!$I$2:$I$501
Name r_sec: Reviews!$J$2:$J$501
Name r_contact: Reviews!$K$2:$K$501
Name r_failed: Reviews!$L$2:$L$501
Name r_sev: Reviews!$M$2:$M$501
Name r_churn: Reviews!$N$2:$N$501
Name r_service: Reviews!$O$2:$O$501
Name r_tagA: Reviews!$S$2:$S$501
Name r_tagB: Reviews!$T$2:$T$501
Name u_primary: 'UC Reviews'!$D$2:$D$501
Name u_contact: 'UC Reviews'!$F$2:$F$501
Name u_sev: 'UC Reviews'!$G$2:$G$501
Name u_churn: 'UC Reviews'!$H$2:$H$501
Name u_star: 'UC Reviews'!$C$2:$C$501
Name n_reviews: Pareto!$D$4
Name n_comp: Pareto!$D$5
Name top3_share: Pareto!$E$20
Name inp_bookings: 'Impact Model'!$C$5
Name inp_rate: 'Impact Model'!$C$6
Name inp_cost: 'Impact Model'!$C$7
Name inp_cut: 'Impact Model'!$C$8
Name inp_lost: 'Impact Model'!$C$9
Name inp_value: 'Impact Model'!$C$10
Name u_comp: Benchmark!$D$4

Sheet Cover
B2: Contact-driver teardown · Yes Madam
B3: 500 real App Store reviews (2026-06-18 to 2026-10-21), tagged into contact drivers
B4: Real public App Store reviews (India), tagged twice with one codebook (AI-assisted), disagreements settled. Names and order IDs removed. Prepared by Chethan.
B6: Top 3 drivers' share of complaints
B7: =top3_share -> 0.59027778 | C7: No-shows & cancellations / Price & offer clarity / Service quality & conduct
B9: How to use
B10: 1. Reviews is the source: every row is one real review with its tags. Change a tag and every tab recalculates.
B11: 2. Pareto and Top Drivers count the tags with COUNTIFS. Impact Model turns them into contacts and rupees: change the yellow assumptions.
B12: 3. Reliability shows two independent taggers' agreement and Cohen's kappa, computed live.
B14: Tabs
B15: Pareto | C15: Complaint drivers, share and running share
B16: Top Drivers | C16: Subtags, severity and quotes for the top 3
B17: Five Whys | C17: Root-cause chains, evidence vs hypothesis
B18: Impact Model | C18: Contacts and rupees, with editable assumptions
B19: Fixes | C19: First three fixes, owner, metric, target, test
B20: Readout | C20: One page: problem, root cause, impact, action
B21: Benchmark | C21: Same method on Urban Company
B22: Trends | C22: By month and by app version
B23: Reliability | C23: Agreement and kappa
B24: Codebook | C24: Driver definitions and rules
B25: JD Map | C25: JD × this teardown × my track record
B26: Reviews | C26: All 500 reviews with tags (names and IDs removed)
B27: UC Reviews | C27: Urban Company tags for the benchmark
B29: Bias: reviews skew negative, iOS-only, and are not ticket data. Use them for the mix of problems, not their rate.

Sheet Pareto
B1: Pareto of complaint drivers
B2: One primary driver per review. Counts are COUNTIFS on the Reviews tab; change a tag there and this recalculates.
B4: Reviews read | D4: =COUNTA(r_n) -> 500
B5: Complaints (not praise) | D5: =COUNTA(r_n)-COUNTIF(r_primary,"praise") -> 288
B6: 1-star reviews | D6: =COUNTIF(r_star,1) -> 227 | E6: =D6/D4 -> 0.454 | F6: of written reviews are 1★, while the store average is 4.73★ across 128,866 ratings. Reviews are a complaint channel.
B8: Driver key | C8: Driver | D8: Reviews | E8: Share of complaints | F8: Running share | G8: Mentioned anywhere | H8: % of driver: contacted support | I8: % of driver: high severity | J8: % of driver: say they'll leave | K8: Top 3? | L8: Share of all who contacted support
B9: partner_cancellation | C9: No-shows & cancellations | D9: =COUNTIF(r_primary,B9) -> 59 | E9: =D9/n_comp -> 0.20486111 | F9: =SUM($D$9:D9)/n_comp -> 0.20486111 | G9: =SUMPRODUCT(--(((r_primary=B9)+ISNUMBER(SEARCH(B9,r_sec)))>0)) -> 68 | H9: =IFERROR(COUNTIFS(r_primary,B9,r_contact,"yes")/D9,0) -> 0.44067797 | I9: =IFERROR(COUNTIFS(r_primary,B9,r_sev,"high")/D9,0) -> 0.016949153 | J9: =IFERROR(COUNTIFS(r_primary,B9,r_churn,"yes")/D9,0) -> 0.16949153 | K9: Yes | L9: =IFERROR(COUNTIFS(r_primary,B9,r_contact,"yes")/COUNTIFS(r_primary,"<>praise",r_contact,"yes"),0) -> 0.36111111
B10: price_clarity | C10: Price & offer clarity | D10: =COUNTIF(r_primary,B10) -> 56 | E10: =D10/n_comp -> 0.19444444 | F10: =SUM($D$9:D10)/n_comp -> 0.39930556 | G10: =SUMPRODUCT(--(((r_primary=B10)+ISNUMBER(SEARCH(B10,r_sec)))>0)) -> 72 | H10: =IFERROR(COUNTIFS(r_primary,B10,r_contact,"yes")/D10,0) -> 0.125 | I10: =IFERROR(COUNTIFS(r_primary,B10,r_sev,"high")/D10,0) -> 0.017857143 | J10: =IFERROR(COUNTIFS(r_primary,B10,r_churn,"yes")/D10,0) -> 0.125 | K10: Yes | L10: =IFERROR(COUNTIFS(r_primary,B10,r_contact,"yes")/COUNTIFS(r_primary,"<>praise",r_contact,"yes"),0) -> 0.097222222
B11: service_quality | C11: Service quality & conduct | D11: =COUNTIF(r_primary,B11) -> 55 | E11: =D11/n_comp -> 0.19097222 | F11: =SUM($D$9:D11)/n_comp -> 0.59027778 | G11: =SUMPRODUCT(--(((r_primary=B11)+ISNUMBER(SEARCH(B11,r_sec)))>0)) -> 73 | H11: =IFERROR(COUNTIFS(r_primary,B11,r_contact,"yes")/D11,0) -> 0.32727273 | I11: =IFERROR(COUNTIFS(r_primary,B11,r_sev,"high")/D11,0) -> 0.4 | J11: =IFERROR(COUNTIFS(r_primary,B11,r_churn,"yes")/D11,0) -> 0.2 | K11: Yes | L11: =IFERROR(COUNTIFS(r_primary,B11,r_contact,"yes")/COUNTIFS(r_primary,"<>praise",r_contact,"yes"),0) -> 0.25
B12: product_fit | C12: Products used | D12: =COUNTIF(r_primary,B12) -> 30 | E12: =D12/n_comp -> 0.10416667 | F12: =SUM($D$9:D12)/n_comp -> 0.69444444 | G12: =SUMPRODUCT(--(((r_primary=B12)+ISNUMBER(SEARCH(B12,r_sec)))>0)) -> 51 | H12: =IFERROR(COUNTIFS(r_primary,B12,r_contact,"yes")/D12,0) -> 0.16666667 | I12: =IFERROR(COUNTIFS(r_primary,B12,r_sev,"high")/D12,0) -> 0.3 | J12: =IFERROR(COUNTIFS(r_primary,B12,r_churn,"yes")/D12,0) -> 0.066666667 | L12: =IFERROR(COUNTIFS(r_primary,B12,r_contact,"yes")/COUNTIFS(r_primary,"<>praise",r_contact,"yes"),0) -> 0.069444444
B13: app | C13: App & booking bugs | D13: =COUNTIF(r_primary,B13) -> 29 | E13: =D13/n_comp -> 0.10069444 | F13: =SUM($D$9:D13)/n_comp -> 0.79513889 | G13: =SUMPRODUCT(--(((r_primary=B13)+ISNUMBER(SEARCH(B13,r_sec)))>0)) -> 58 | H13: =IFERROR(COUNTIFS(r_primary,B13,r_contact,"yes")/D13,0) -> 0.17241379 | I13: =IFERROR(COUNTIFS(r_primary,B13,r_sev,"high")/D13,0) -> 0.068965517 | J13: =IFERROR(COUNTIFS(r_primary,B13,r_churn,"yes")/D13,0) -> 0.068965517 | L13: =IFERROR(COUNTIFS(r_primary,B13,r_contact,"yes")/COUNTIFS(r_primary,"<>praise",r_contact,"yes"),0) -> 0.069444444
B14: payment_refund | C14: Payments & refunds | D14: =COUNTIF(r_primary,B14) -> 12 | E14: =D14/n_comp -> 0.041666667 | F14: =SUM($D$9:D14)/n_comp -> 0.83680556 | G14: =SUMPRODUCT(--(((r_primary=B14)+ISNUMBER(SEARCH(B14,r_sec)))>0)) -> 25 | H14: =IFERROR(COUNTIFS(r_primary,B14,r_contact,"yes")/D14,0) -> 0.5 | I14: =IFERROR(COUNTIFS(r_primary,B14,r_sev,"high")/D14,0) -> 1 | J14: =IFERROR(COUNTIFS(r_primary,B14,r_churn,"yes")/D14,0) -> 0 | L14: =IFERROR(COUNTIFS(r_primary,B14,r_contact,"yes")/COUNTIFS(r_primary,"<>praise",r_contact,"yes"),0) -> 0.083333333
B15: support | C15: Support itself | D15: =COUNTIF(r_primary,B15) -> 5 | E15: =D15/n_comp -> 0.017361111 | F15: =SUM($D$9:D15)/n_comp -> 0.85416667 | G15: =SUMPRODUCT(--(((r_primary=B15)+ISNUMBER(SEARCH(B15,r_sec)))>0)) -> 71 | H15: =IFERROR(COUNTIFS(r_primary,B15,r_contact,"yes")/D15,0) -> 0.6 | I15: =IFERROR(COUNTIFS(r_primary,B15,r_sev,"high")/D15,0) -> 0 | J15: =IFERROR(COUNTIFS(r_primary,B15,r_churn,"yes")/D15,0) -> 0.2 | L15: =IFERROR(COUNTIFS(r_primary,B15,r_contact,"yes")/COUNTIFS(r_primary,"<>praise",r_contact,"yes"),0) -> 0.041666667
B16: delay | C16: Late arrivals | D16: =COUNTIF(r_primary,B16) -> 4 | E16: =D16/n_comp -> 0.013888889 | F16: =SUM($D$9:D16)/n_comp -> 0.86805556 | G16: =SUMPRODUCT(--(((r_primary=B16)+ISNUMBER(SEARCH(B16,r_sec)))>0)) -> 21 | H16: =IFERROR(COUNTIFS(r_primary,B16,r_contact,"yes")/D16,0) -> 0.5 | I16: =IFERROR(COUNTIFS(r_primary,B16,r_sev,"high")/D16,0) -> 0 | J16: =IFERROR(COUNTIFS(r_primary,B16,r_churn,"yes")/D16,0) -> 0 | L16: =IFERROR(COUNTIFS(r_primary,B16,r_contact,"yes")/COUNTIFS(r_primary,"<>praise",r_contact,"yes"),0) -> 0.027777778
B17: other | C17: Other or vague | D17: =COUNTIF(r_primary,B17) -> 38 | E17: =D17/n_comp -> 0.13194444 | F17: =SUM($D$9:D17)/n_comp -> 1 | G17: =SUMPRODUCT(--(((r_primary=B17)+ISNUMBER(SEARCH(B17,r_sec)))>0)) -> 40 | H17: =IFERROR(COUNTIFS(r_primary,B17,r_contact,"yes")/D17,0) -> 0 | I17: =IFERROR(COUNTIFS(r_primary,B17,r_sev,"high")/D17,0) -> 0 | J17: =IFERROR(COUNTIFS(r_primary,B17,r_churn,"yes")/D17,0) -> 0.10526316 | L17: =IFERROR(COUNTIFS(r_primary,B17,r_contact,"yes")/COUNTIFS(r_primary,"<>praise",r_contact,"yes"),0) -> 0
C18: All complaints | D18: =SUM(D9:D17) -> 288 | E18: =SUM(E9:E17) -> 1 | F18: =IF(D18=n_comp,"Ties to complaint count","Does not tie: check tags") -> Ties to complaint count
C20: Top 3 drivers' share of complaints | E20: =SUMIFS(D9:D17,K9:K17,"Yes")/n_comp -> 0.59027778
C21: Top 3 drivers' share of those who contacted support | E21: =SUMIFS(L9:L17,K9:K17,"Yes") -> 0.70833333 | F21: Weighted by reviews that say they already contacted support: the better proxy for contacts, on a smaller sample

Sheet Top Drivers
B1: The top three drivers
B2: Subtags, contact and severity for each, plus the quotes used on slide 2.
B4: #1 No-shows & cancellations | F4: =COUNTIF(r_primary,"partner_cancellation") -> 59 | G4: =F4/n_comp -> 0.20486111 | H4: of complaints
B5: Subtag | C5: Label | D5: Reviews | E5: Share of driver
B6: last_minute_cancel | C6: Cancelled at the last minute | D6: =COUNTIFS(r_primary,"partner_cancellation",r_sub,B6) -> 25 | E6: =D6/COUNTIF(r_primary,"partner_cancellation") -> 0.42372881
B7: no_show | C7: Didn't show up | D7: =COUNTIFS(r_primary,"partner_cancellation",r_sub,B7) -> 20 | E7: =D7/COUNTIF(r_primary,"partner_cancellation") -> 0.33898305
B8: repeated_reschedule | C8: Rescheduled again and again | D8: =COUNTIFS(r_primary,"partner_cancellation",r_sub,B8) -> 8 | E8: =D8/COUNTIF(r_primary,"partner_cancellation") -> 0.13559322
B9: no_partner_available | C9: No professional available | D9: =COUNTIFS(r_primary,"partner_cancellation",r_sub,B9) -> 6 | E9: =D9/COUNTIF(r_primary,"partner_cancellation") -> 0.10169492
C10: Contacted support | E10: =COUNTIFS(r_primary,"partner_cancellation",r_contact,"yes")/COUNTIF(r_primary,"partner_cancellation") -> 0.44067797
C11: High severity | E11: =COUNTIFS(r_primary,"partner_cancellation",r_sev,"high")/COUNTIF(r_primary,"partner_cancellation") -> 0.016949153
C12: Say they'll leave | E12: =COUNTIFS(r_primary,"partner_cancellation",r_churn,"yes")/COUNTIF(r_primary,"partner_cancellation") -> 0.16949153
C13: Quotes
C14: "I booked a service for 4:30 PM today, and instead of informing me beforehand, they called me at exactly 4:30 PM to say that no professional was available" | I14: 1★ · 2026-08-02
C15: "professional refused to come and asked me to cancel and when I told her u cancel she kept calling me till I cancelled it." | I15: 1★ · 2026-09-05
C16: "Twice professionals didn’t show up. No cancellations, no notice, just plain didn’t show up." | I16: 1★ · 2026-10-16
B19: #2 Price & offer clarity | F19: =COUNTIF(r_primary,"price_clarity") -> 56 | G19: =F19/n_comp -> 0.19444444 | H19: of complaints
B20: Subtag | C20: Label | D20: Reviews | E20: Share of driver
B21: offer_not_honoured | C21: Offer or coupon not honoured | D21: =COUNTIFS(r_primary,"price_clarity",r_sub,B21) -> 34 | E21: =D21/COUNTIF(r_primary,"price_clarity") -> 0.60714286
B22: hidden_charges | C22: Extra charges at checkout | D22: =COUNTIFS(r_primary,"price_clarity",r_sub,B22) -> 15 | E22: =D22/COUNTIF(r_primary,"price_clarity") -> 0.26785714
B23: membership_or_package_confusion | C23: Membership or package confusion | D23: =COUNTIFS(r_primary,"price_clarity",r_sub,B23) -> 4 | E23: =D23/COUNTIF(r_primary,"price_clarity") -> 0.071428571
B24: price_mismatch | C24: Price different from shown | D24: =COUNTIFS(r_primary,"price_clarity",r_sub,B24) -> 3 | E24: =D24/COUNTIF(r_primary,"price_clarity") -> 0.053571429
C25: Contacted support | E25: =COUNTIFS(r_primary,"price_clarity",r_contact,"yes")/COUNTIF(r_primary,"price_clarity") -> 0.125
C26: High severity | E26: =COUNTIFS(r_primary,"price_clarity",r_sev,"high")/COUNTIF(r_primary,"price_clarity") -> 0.017857143
C27: Say they'll leave | E27: =COUNTIFS(r_primary,"price_clarity",r_churn,"yes")/COUNTIF(r_primary,"price_clarity") -> 0.125
C28: Quotes
C29: "The first 2 days the slots were already over by 1:02 pm." | I29: 3★ · 2026-10-09
C30: "If I’m booking a spa for 970 it sums up to 1399 by the end of the payment" | I30: 2★ · 2026-10-19
C31: "while booking I get to know there are platform charges, mandatory disposable kit charges which resulted me to pay extra amount unnecessarily." | I31: 2★ · 2026-10-11
B34: #3 Service quality & conduct | F34: =COUNTIF(r_primary,"service_quality") -> 55 | G34: =F34/n_comp -> 0.19097222 | H34: of complaints
B35: Subtag | C35: Label | D35: Reviews | E35: Share of driver
B36: poor_skill | C36: Poor skill | D36: =COUNTIFS(r_primary,"service_quality",r_sub,B36) -> 20 | E36: =D36/COUNTIF(r_primary,"service_quality") -> 0.36363636
B37: skin_injury_or_reaction | C37: Burn, cut or rash | D37: =COUNTIFS(r_primary,"service_quality",r_sub,B37) -> 17 | E37: =D37/COUNTIF(r_primary,"service_quality") -> 0.30909091
B38: rushed_or_incomplete | C38: Rushed or incomplete | D38: =COUNTIFS(r_primary,"service_quality",r_sub,B38) -> 9 | E38: =D38/COUNTIF(r_primary,"service_quality") -> 0.16363636
B39: hygiene | C39: Hygiene | D39: =COUNTIFS(r_primary,"service_quality",r_sub,B39) -> 3 | E39: =D39/COUNTIF(r_primary,"service_quality") -> 0.054545455
B40: safety_or_theft | C40: Safety, privacy or theft | D40: =COUNTIFS(r_primary,"service_quality",r_sub,B40) -> 3 | E40: =D40/COUNTIF(r_primary,"service_quality") -> 0.054545455
B41: rude_behaviour | C41: Rude behaviour | D41: =COUNTIFS(r_primary,"service_quality",r_sub,B41) -> 3 | E41: =D41/COUNTIF(r_primary,"service_quality") -> 0.054545455
C42: Contacted support | E42: =COUNTIFS(r_primary,"service_quality",r_contact,"yes")/COUNTIF(r_primary,"service_quality") -> 0.32727273
C43: High severity | E43: =COUNTIFS(r_primary,"service_quality",r_sev,"high")/COUNTIF(r_primary,"service_quality") -> 0.4
C44: Say they'll leave | E44: =COUNTIFS(r_primary,"service_quality",r_churn,"yes")/COUNTIF(r_primary,"service_quality") -> 0.2
C45: Quotes
...

Sheet Five Whys
B1: Root causes: five whys on the top three drivers
B2: "In reviews" = customers say it. "To verify" = my hypothesis, to check against ticket and ops data.
B4: No-shows & cancellations
B5: Problem | C5: Bookings fail at or after the slot time, and the customer is the last to know.
B6: Why | C6: Answer | F6: Evidence
B7: Why 1 | C7: The assigned professional declined, went on leave or fell ill, and no one else was sent (#62, #247, #250). | F7: In reviews
B8: Why 2 | C8: Nobody checks before the slot that she is coming. The customer finds out at the slot time, or only when she calls support (#15, #193, #338). | F8: In reviews
B9: Why 3 | C9: Accepting a job does not lock the professional in: some call and ask the customer to cancel instead (#127, #219, #362). | F9: In reviews
B10: Why 4 | C10: The app shows slots when no professional is free, and products run short too, so there is no one ready to send instead (#73, #284, #394). | F10: In reviews
B11: Why 5 | C11: Slots are sold off the calendar, not off confirmed professional capacity in that area and hour, and payment is taken before anyone confirms. | F11: To verify
B12: Root cause | C12: Slots are sold before a professional is confirmed, and nothing checks or backfills a dropped job before the slot time.
B13: Would prove me wrong | C13: If most failed bookings had a professional confirmed 2 hours before the slot and still failed, the problem is on-the-day behaviour, not slot inventory.
B16: Price & offer clarity
B17: Problem | C17: Customers feel tricked: the free offer is gone in a minute, and the price grows at checkout.
B18: Why | C18: Answer | F18: Evidence
B19: Why 1 | C19: The offer they were sent could not be booked, or the final price was higher than the price shown (#10, #23). | F19: In reviews
B20: Why 2 | C20: The free pedicure opens at 1 pm for everyone. Slots are gone by 1:02, and the app crashes at checkout in the rush (#78, #121, #138). | F20: In reviews
B21: Why 3 | C21: It reads as a scam, not a sell-out: customers call it 'fake' and 'bluffing', and nothing tells them how few slots there were (#48, #77, #121). | F21: In reviews
B22: Why 4 | C22: Compulsory fees sit outside the listed price: a platform fee, a ₹99 kit charge, a ₹300 line labelled tax. They appear only at checkout (#55, #126, #190). | F22: In reviews
B23: Why 5 | C23: Offers and price pages are judged on installs and visits, not on how many offers are honoured or how many complaints they create. | F23: To verify
B24: Root cause | C24: Offers and prices are built to attract, not to be honoured: a flash offer that sells out in minutes is pushed to everyone, and compulsory fees show up only at checkout.
B25: Would prove me wrong | C25: If offer complaints spike only on days the app crashed at 1 pm, this is an engineering capacity problem, not offer design.
B28: Service quality & conduct
B29: Problem | C29: The service itself goes wrong: untrained or rushed work, rude behaviour, and burns or rashes (11 of the 24 burn or reaction reviews follow waxing).
B30: Why | C30: Answer | F30: Evidence
B31: Why 1 | C31: The professional lacked the skill for that service: burnt skin after waxing, ruined brows (#41, #152, #191). | F31: In reviews
B32: Why 2 | C32: Professionals reach customers before their skill on each service is proven. Quality is checked by ratings after the job, not before it. | F32: To verify
B33: Why 3 | C33: Professionals rush the job: 'in too much hurry', a facial done in 30 minutes (#50, #264, #351). | F33: In reviews
B34: Why 4 | C34: When something goes wrong, there is no real follow-up: a ₹400 coupon for a burnt hand, no reply to photos of a burn, a promised refund that never came (#41, #217, #104). | F34: In reviews
B35: Why 5 | C35: Complaints are closed case by case in support and don't flow back to the professional's record, training or assignment. | F35: To verify
B36: Root cause | C36: No closed loop from complaint to professional: skill isn't certified per service before risky jobs like waxing, and complaints end in coupons instead of retraining.
B37: Would prove me wrong | C37: If complaints are spread evenly across professionals rather than concentrated in a few, the problem is training content or products, not specific people.

Sheet Impact Model
B1: Impact in contacts and rupees
B2: Yellow cells are assumptions. Change them and everything below updates. Driver mix comes from the Pareto tab.
B4: Assumption | C4: Value | D4: Note
B5: Bookings a month | C5: 350000 | D5: Public figure: about 3.5 lakh bookings a month
B6: Contacts per 100 bookings | C6: 12 | D6: Assumption. Typical for at-home services: 8–15. Replace with the real number
B7: Cost per contact (₹) | C7: 45 | D7: Assumption: blended chat and voice
B8: Cut in top-3 contacts from the fixes | C8: 0.3 | D8: Target for the three fixes
B9: Customers lost per top-3 contact | C9: 0.1 | D9: Reviews say 16%; the real rate is lower, so this is cautious
B10: Yearly value of a customer (₹) | C10: 5400 | D10: Assumption: about ₹1,350 a visit, 4 visits a year
B13: Result | C13: Value | D13: How
B14: Contacts a month | C14: =inp_bookings*inp_rate/100 -> 42000 | D14: bookings × contacts per 100
B15: Support cost a month | C15: =C14*inp_cost -> 1890000 | D15: contacts × cost per contact
B16: Contacts from the top 3 drivers | C16: =C14*top3_share -> 24791.667 | D16: contacts × top-3 share of complaints
B17: Contacts removed a month | C17: =C16*inp_cut -> 7437.5 | D17: top-3 contacts × cut
B18: Support cost saved a year | C18: =C17*inp_cost*12 -> 4016250 | D18: removed contacts × cost × 12
B19: Customers kept a month | C19: =C17*inp_lost -> 743.75 | D19: removed contacts × customers lost per contact
B20: Revenue kept a year (up to) | C20: =C19*12*inp_value -> 48195000 | D20: customers kept × 12 × yearly value
B23: By driver, per month
B24: Driver | C24: Share | D24: Contacts | E24: Cost | F24: After fixes
B25: No-shows & cancellations | C25: =Pareto!E9 -> 0.20486111 | D25: =$C$14*C25 -> 8604.1667 | E25: =D25*inp_cost -> 387187.5 | F25: =IF(Pareto!K9="Yes",D25*(1-inp_cut),D25) -> 6022.9167
B26: Price & offer clarity | C26: =Pareto!E10 -> 0.19444444 | D26: =$C$14*C26 -> 8166.6667 | E26: =D26*inp_cost -> 367500 | F26: =IF(Pareto!K10="Yes",D26*(1-inp_cut),D26) -> 5716.6667
B27: Service quality & conduct | C27: =Pareto!E11 -> 0.19097222 | D27: =$C$14*C27 -> 8020.8333 | E27: =D27*inp_cost -> 360937.5 | F27: =IF(Pareto!K11="Yes",D27*(1-inp_cut),D27) -> 5614.5833
B28: Products used | C28: =Pareto!E12 -> 0.10416667 | D28: =$C$14*C28 -> 4375 | E28: =D28*inp_cost -> 196875 | F28: =IF(Pareto!K12="Yes",D28*(1-inp_cut),D28) -> 4375
B29: App & booking bugs | C29: =Pareto!E13 -> 0.10069444 | D29: =$C$14*C29 -> 4229.1667 | E29: =D29*inp_cost -> 190312.5 | F29: =IF(Pareto!K13="Yes",D29*(1-inp_cut),D29) -> 4229.1667
B30: Payments & refunds | C30: =Pareto!E14 -> 0.041666667 | D30: =$C$14*C30 -> 1750 | E30: =D30*inp_cost -> 78750 | F30: =IF(Pareto!K14="Yes",D30*(1-inp_cut),D30) -> 1750
B31: Support itself | C31: =Pareto!E15 -> 0.017361111 | D31: =$C$14*C31 -> 729.16667 | E31: =D31*inp_cost -> 32812.5 | F31: =IF(Pareto!K15="Yes",D31*(1-inp_cut),D31) -> 729.16667
B32: Late arrivals | C32: =Pareto!E16 -> 0.013888889 | D32: =$C$14*C32 -> 583.33333 | E32: =D32*inp_cost -> 26250 | F32: =IF(Pareto!K16="Yes",D32*(1-inp_cut),D32) -> 583.33333
B33: Other or vague | C33: =Pareto!E17 -> 0.13194444 | D33: =$C$14*C33 -> 5541.6667 | E33: =D33*inp_cost -> 249375 | F33: =IF(Pareto!K17="Yes",D33*(1-inp_cut),D33) -> 5541.6667
B34: Total | C34: =SUM(C25:C33) -> 1 | D34: =SUM(D25:D33) -> 42000 | E34: =SUM(E25:E33) -> 1890000 | F34: =SUM(F25:F33) -> 34562.5
B36: Caveat: the driver mix comes from reviews, which over-weight severe problems. Real ticket data would replace it in week 1.

Sheet Fixes
B1: First three fixes, and how I'd measure them
B2: One fix per top driver. Each has an owner, one metric, a target and a test.
B4: Fix | C4: Driver | D4: Owner | E4: What changes | F4: Metric | G4: Target | H4: How I'd measure it
B5: Confirm or reassign 2 hours before | C5: No-shows & cancellations | D5: City Ops, Supply and Product | E5: Professional confirms 2 hours before the slot. No confirmation means auto-reassign from the nearby pool, and the customer gets a message with a choice before the slot, not after. Sell slots only against confirmed capacity. Log a professional's 'please cancel' as a partner cancellation. | F5: Failed bookings per 100, partner side | G5: Down 40% in 8 weeks; 90% of failures with 2+ hours' notice | H5: Pilot in 2 cities against 2 similar cities for 4 weeks. Track failed bookings, notice given, reassign success, and contacts per 100 bookings for 'where is my professional'.
B6: Price shown is price paid; honest offers | C6: Price & offer clarity | D6: Growth, Product and Finance | E6: Show compulsory fees inside the listed price. Label flash offers with the number of slots ('200 free pedicures today') and give a waitlist or coupon when they run out. Load-test the 1 pm checkout. | F6: Offer and price complaints per 1,000 bookings | G6: Down 50%, with checkout conversion flat or better | H6: A/B test all-in prices on 10% of users for 2 weeks: conversion, cart-to-payment drop-off, and contacts tagged offer or charges. Track app crashes in the 1 pm window.
B7: Certify risky services; close the loop on complaints | C7: Service quality & conduct | D7: Training & QA and CX | E7: Certify each professional per service, waxing first, before she is assigned it. Every injury complaint gets a call within 24 hours, care for the customer, and the professional is paused and retrained. Weekly list of professionals with 2+ complaints. | F7: Injury and quality complaints per 1,000 jobs | G7: Down 30% in 12 weeks; no repeat complaint within 30 days of retraining | H7: Before and after by hub cohort. Check how concentrated complaints are: if the worst 10% of professionals carry most of them, target them first.
B9: First 30 days
B10: • | C10: Week 1: pull the last 90 days of support tickets and tag them with this codebook. Compare the ticket mix with this review mix.
B11: • | C11: Week 2: put rupees on each driver from real data: contacts, refunds, compensation coupons and lost repeat bookings.
B12: • | C12: Week 3: start the two pilots: confirm-or-reassign in 2 cities, and all-in prices for 10% of users.
B13: • | C13: Week 4: first readout to you, and a weekly contacts-per-100-bookings view by driver.

Sheet Readout
B1: One-page readout
B2: Why customers contact Yes Madam, and what to fix first.
B4: Problem
B5: • | C5: Customers who write reviews are mostly unhappy: 58% of the 500 most recent App Store reviews are complaints and 45% are 1★, against a 4.73★ store average.
B6: • | C6: 59% of complaints come from three drivers: no-shows and cancellations (20%), price and offer clarity (19%) and service quality (19%).
B7: • | C7: 25% of complaints say they already contacted support, and the same three drivers are 71% of those; no-shows and cancellations alone are 36%. 13% say they will stop using the app.
B9: Root cause
B10: • | C10: Slots are sold before a professional is confirmed, and nothing checks or backfills a dropped job before the slot time.
B11: • | C11: Offers and prices are built to attract, not to be honoured: a flash offer that sells out in minutes is pushed to everyone, and compulsory fees show up only at checkout.
B12: • | C12: No closed loop from complaint to professional: skill isn't certified per service before risky jobs like waxing, and complaints end in coupons instead of retraining.
B14: Impact
B15: • | C15: At about 3.5 lakh bookings a month and an assumed 12 contacts per 100 bookings, that is about 42,000 contacts a month.
B16: • | C16: The top three drivers would be about 59% of them, about 24,800 a month. A 30% cut removes about 7,400 contacts a month, or ₹40.2 L a year at ₹45 a contact.
B17: • | C17: The bigger prize is retention: if 1 in 10 customers behind those bad experiences would otherwise leave, keeping them is worth up to ₹4.8 Cr a year at ₹5,400 a customer.
B19: Action
B20: • | C20: Confirm or reassign 2 hours before: failed bookings per 100, partner side, down 40% in 8 weeks; 90% of failures with 2+ hours' notice.
B21: • | C21: Price shown is price paid; honest offers: offer and price complaints per 1,000 bookings, down 50%, with checkout conversion flat or better.
B22: • | C22: Certify risky services; close the loop on complaints: injury and quality complaints per 1,000 jobs, down 30% in 12 weeks; no repeat complaint within 30 days of retraining.
B24: Based on 500 public App Store reviews, which skew negative and towards iPhone users, and are not ticket data. Use them for the mix of problems; confirm the size with support tickets in week 1.

Sheet Benchmark
B1: Benchmark: Urban Company
B2: Same codebook on Urban Company's 500 most recent App Store reviews. Urban Company covers all home services.
B4: Urban Company complaints | D4: =COUNTA(u_primary)-COUNTIF(u_primary,"praise") -> 301
B6: Driver key | C6: Driver | D6: Yes Madam | E6: Urban Company | F6: Gap (pts)
B7: partner_cancellation | C7: No-shows & cancellations | D7: =COUNTIF(r_primary,B7)/n_comp -> 0.20486111 | E7: =COUNTIF(u_primary,B7)/u_comp -> 0.24584718 | F7: =(D7-E7)*100 -> -4.0986065
B8: price_clarity | C8: Price & offer clarity | D8: =COUNTIF(r_primary,B8)/n_comp -> 0.19444444 | E8: =COUNTIF(u_primary,B8)/u_comp -> 0.1627907 | F8: =(D8-E8)*100 -> 3.1653747
B9: service_quality | C9: Service quality & conduct | D9: =COUNTIF(r_primary,B9)/n_comp -> 0.19097222 | E9: =COUNTIF(u_primary,B9)/u_comp -> 0.18272425 | F9: =(D9-E9)*100 -> 0.82479697
B10: product_fit | C10: Products used | D10: =COUNTIF(r_primary,B10)/n_comp -> 0.10416667 | E10: =COUNTIF(u_primary,B10)/u_comp -> 0.026578073 | F10: =(D10-E10)*100 -> 7.7588594
B11: app | C11: App & booking bugs | D11: =COUNTIF(r_primary,B11)/n_comp -> 0.10069444 | E11: =COUNTIF(u_primary,B11)/u_comp -> 0.053156146 | F11: =(D11-E11)*100 -> 4.7538298
B12: payment_refund | C12: Payments & refunds | D12: =COUNTIF(r_primary,B12)/n_comp -> 0.041666667 | E12: =COUNTIF(u_primary,B12)/u_comp -> 0.089700997 | F12: =(D12-E12)*100 -> -4.803433
B13: support | C13: Support itself | D13: =COUNTIF(r_primary,B13)/n_comp -> 0.017361111 | E13: =COUNTIF(u_primary,B13)/u_comp -> 0.07641196 | F13: =(D13-E13)*100 -> -5.9050849
B14: delay | C14: Late arrivals | D14: =COUNTIF(r_primary,B14)/n_comp -> 0.013888889 | E14: =COUNTIF(u_primary,B14)/u_comp -> 0.016611296 | F14: =(D14-E14)*100 -> -0.27224068
B15: other | C15: Other or vague | D15: =COUNTIF(r_primary,B15)/n_comp -> 0.13194444 | E15: =COUNTIF(u_primary,B15)/u_comp -> 0.1461794 | F15: =(D15-E15)*100 -> -1.4234958
B17: Contacted support (share of complaints) | D17: =COUNTIF(r_contact,"yes")/n_comp -> 0.25 | E17: =COUNTIF(u_contact,"yes")/u_comp -> 0.34219269
B18: High severity | D18: =COUNTIF(r_sev,"high")/n_comp -> 0.16319444 | E18: =COUNTIF(u_sev,"high")/u_comp -> 0.2192691
B19: Say they'll leave | D19: =COUNTIF(r_churn,"yes")/n_comp -> 0.12847222 | E19: =COUNTIF(u_churn,"yes")/u_comp -> 0.11960133

Sheet Trends
B1: Trends
B2: Complaint reviews by month and driver, and app complaints by app version.
B4: Driver | C4: 2026-06 | D4: 2026-07 | E4: 2026-08 | F4: 2026-09 | G4: 2026-10 | H4: Total
B5: No-shows & cancellations | C5: =COUNTIFS(r_primary,"partner_cancellation",r_month,"2026-06") -> 4 | D5: =COUNTIFS(r_primary,"partner_cancellation",r_month,"2026-07") -> 11 | E5: =COUNTIFS(r_primary,"partner_cancellation",r_month,"2026-08") -> 22 | F5: =COUNTIFS(r_primary,"partner_cancellation",r_month,"2026-09") -> 11 | G5: =COUNTIFS(r_primary,"partner_cancellation",r_month,"2026-10") -> 11 | H5: =SUM(C5:G5) -> 59
B6: Price & offer clarity | C6: =COUNTIFS(r_primary,"price_clarity",r_month,"2026-06") -> 2 | D6: =COUNTIFS(r_primary,"price_clarity",r_month,"2026-07") -> 6 | E6: =COUNTIFS(r_primary,"price_clarity",r_month,"2026-08") -> 3 | F6: =COUNTIFS(r_primary,"price_clarity",r_month,"2026-09") -> 29 | G6: =COUNTIFS(r_primary,"price_clarity",r_month,"2026-10") -> 16 | H6: =SUM(C6:G6) -> 56
B7: Service quality & conduct | C7: =COUNTIFS(r_primary,"service_quality",r_month,"2026-06") -> 4 | D7: =COUNTIFS(r_primary,"service_quality",r_month,"2026-07") -> 9 | E7: =COUNTIFS(r_primary,"service_quality",r_month,"2026-08") -> 19 | F7: =COUNTIFS(r_primary,"service_quality",r_month,"2026-09") -> 11 | G7: =COUNTIFS(r_primary,"service_quality",r_month,"2026-10") -> 12 | H7: =SUM(C7:G7) -> 55
B8: Products used | C8: =COUNTIFS(r_primary,"product_fit",r_month,"2026-06") -> 3 | D8: =COUNTIFS(r_primary,"product_fit",r_month,"2026-07") -> 11 | E8: =COUNTIFS(r_primary,"product_fit",r_month,"2026-08") -> 3 | F8: =COUNTIFS(r_primary,"product_fit",r_month,"2026-09") -> 7 | G8: =COUNTIFS(r_primary,"product_fit",r_month,"2026-10") -> 6 | H8: =SUM(C8:G8) -> 30
B9: App & booking bugs | C9: =COUNTIFS(r_primary,"app",r_month,"2026-06") -> 0 | D9: =COUNTIFS(r_primary,"app",r_month,"2026-07") -> 5 | E9: =COUNTIFS(r_primary,"app",r_month,"2026-08") -> 2 | F9: =COUNTIFS(r_primary,"app",r_month,"2026-09") -> 7 | G9: =COUNTIFS(r_primary,"app",r_month,"2026-10") -> 15 | H9: =SUM(C9:G9) -> 29
B10: Payments & refunds | C10: =COUNTIFS(r_primary,"payment_refund",r_month,"2026-06") -> 0 | D10: =COUNTIFS(r_primary,"payment_refund",r_month,"2026-07") -> 1 | E10: =COUNTIFS(r_primary,"payment_refund",r_month,"2026-08") -> 4 | F10: =COUNTIFS(r_primary,"payment_refund",r_month,"2026-09") -> 5 | G10: =COUNTIFS(r_primary,"payment_refund",r_month,"2026-10") -> 2 | H10: =SUM(C10:G10) -> 12
B11: Support itself | C11: =COUNTIFS(r_primary,"support",r_month,"2026-06") -> 0 | D11: =COUNTIFS(r_primary,"support",r_month,"2026-07") -> 2 | E11: =COUNTIFS(r_primary,"support",r_month,"2026-08") -> 0 | F11: =COUNTIFS(r_primary,"support",r_month,"2026-09") -> 3 | G11: =COUNTIFS(r_primary,"support",r_month,"2026-10") -> 0 | H11: =SUM(C11:G11) -> 5
B12: Late arrivals | C12: =COUNTIFS(r_primary,"delay",r_month,"2026-06") -> 0 | D12: =COUNTIFS(r_primary,"delay",r_month,"2026-07") -> 0 | E12: =COUNTIFS(r_primary,"delay",r_month,"2026-08") -> 2 | F12: =COUNTIFS(r_primary,"delay",r_month,"2026-09") -> 2 | G12: =COUNTIFS(r_primary,"delay",r_month,"2026-10") -> 0 | H12: =SUM(C12:G12) -> 4
B13: Other or vague | C13: =COUNTIFS(r_primary,"other",r_month,"2026-06") -> 5 | D13: =COUNTIFS(r_primary,"other",r_month,"2026-07") -> 17 | E13: =COUNTIFS(r_primary,"other",r_month,"2026-08") -> 5 | F13: =COUNTIFS(r_primary,"other",r_month,"2026-09") -> 7 | G13: =COUNTIFS(r_primary,"other",r_month,"2026-10") -> 4 | H13: =SUM(C13:G13) -> 38
B14: All complaints | C14: =SUM(C5:C13) -> 18 | D14: =SUM(D5:D13) -> 62 | E14: =SUM(E5:E13) -> 60 | F14: =SUM(F5:F13) -> 82 | G14: =SUM(G5:G13) -> 66 | H14: =SUM(H5:H13) -> 288
B15: All reviews | C15: =COUNTIF(r_month,"2026-06") -> 40 | D15: =COUNTIF(r_month,"2026-07") -> 117 | E15: =COUNTIF(r_month,"2026-08") -> 113 | F15: =COUNTIF(r_month,"2026-09") -> 126 | G15: =COUNTIF(r_month,"2026-10") -> 104
B16: 2026-06 starts on 2026-06-18; 2026-10 runs to 2026-10-21. Both are part months.
B18: App complaints by app version
B19: Version | C19: Reviews | D19: App complaints | E19: Share
B20: 18.9.0 | C20: =COUNTIF(r_ver,B20) -> 87 | D20: =COUNTIFS(r_ver,B20,r_primary,"app") -> 10 | E20: =IFERROR(D20/C20,0) -> 0.11494253
B21: 18.8.0 | C21: =COUNTIF(r_ver,B21) -> 100 | D21: =COUNTIFS(r_ver,B21,r_primary,"app") -> 9 | E21: =IFERROR(D21/C21,0) -> 0.09
B22: 18.7.0 | C22: =COUNTIF(r_ver,B22) -> 70 | D22: =COUNTIFS(r_ver,B22,r_primary,"app") -> 3 | E22: =IFERROR(D22/C22,0) -> 0.042857143
B23: 18.6.0 | C23: =COUNTIF(r_ver,B23) -> 17 | D23: =COUNTIFS(r_ver,B23,r_primary,"app") -> 0 | E23: =IFERROR(D23/C23,0) -> 0
B24: 18.5.0 | C24: =COUNTIF(r_ver,B24) -> 133 | D24: =COUNTIFS(r_ver,B24,r_primary,"app") -> 5 | E24: =IFERROR(D24/C24,0) -> 0.037593985
B25: 18.2.0 | C25: =COUNTIF(r_ver,B25) -> 93 | D25: =COUNTIFS(r_ver,B25,r_primary,"app") -> 2 | E25: =IFERROR(D25/C25,0) -> 0.021505376

Sheet Reliability
B1: Tagging reliability
B2: Every review was tagged in two independent passes with the same codebook. Agreement and Cohen's kappa are computed live from the Reviews tab.
B4: Reviews double-tagged | E4: =SUMPRODUCT(--(r_tagA<>""),--(r_tagB<>"")) -> 500
B5: Same primary driver | E5: =SUMPRODUCT(--(r_tagA=r_tagB),--(r_tagA<>"")) -> 492
B6: Observed agreement (po) | E6: =E5/E4 -> 0.984
B8: Driver | C8: Tagger A count | D8: Tagger B count | E8: Chance agreement
B9: partner_cancellation | C9: =COUNTIF(r_tagA,B9) -> 59 | D9: =COUNTIF(r_tagB,B9) -> 59 | E9: =(C9/$E$4)*(D9/$E$4) -> 0.013924
B10: price_clarity | C10: =COUNTIF(r_tagA,B10) -> 55 | D10: =COUNTIF(r_tagB,B10) -> 56 | E10: =(C10/$E$4)*(D10/$E$4) -> 0.01232
B11: service_quality | C11: =COUNTIF(r_tagA,B11) -> 55 | D11: =COUNTIF(r_tagB,B11) -> 56 | E11: =(C11/$E$4)*(D11/$E$4) -> 0.01232
B12: product_fit | C12: =COUNTIF(r_tagA,B12) -> 30 | D12: =COUNTIF(r_tagB,B12) -> 30 | E12: =(C12/$E$4)*(D12/$E$4) -> 0.0036
B13: app | C13: =COUNTIF(r_tagA,B13) -> 30 | D13: =COUNTIF(r_tagB,B13) -> 30 | E13: =(C13/$E$4)*(D13/$E$4) -> 0.0036
B14: payment_refund | C14: =COUNTIF(r_tagA,B14) -> 12 | D14: =COUNTIF(r_tagB,B14) -> 10 | E14: =(C14/$E$4)*(D14/$E$4) -> 0.00048
B15: support | C15: =COUNTIF(r_tagA,B15) -> 5 | D15: =COUNTIF(r_tagB,B15) -> 5 | E15: =(C15/$E$4)*(D15/$E$4) -> 0.0001
B16: delay | C16: =COUNTIF(r_tagA,B16) -> 4 | D16: =COUNTIF(r_tagB,B16) -> 5 | E16: =(C16/$E$4)*(D16/$E$4) -> 8e-05
B17: other | C17: =COUNTIF(r_tagA,B17) -> 37 | D17: =COUNTIF(r_tagB,B17) -> 37 | E17: =(C17/$E$4)*(D17/$E$4) -> 0.005476
B18: praise | C18: =COUNTIF(r_tagA,B18) -> 213 | D18: =COUNTIF(r_tagB,B18) -> 212 | E18: =(C18/$E$4)*(D18/$E$4) -> 0.180624
B19: Chance agreement (pe) | E19: =SUM(E9:E18) -> 0.232524
B20: Cohen's kappa = (po − pe) ÷ (1 − pe) | E20: =(E6-E19)/(1-E19) -> 0.97915244
B21: Reading: above 0.6 is substantial agreement, above 0.8 near-perfect. Disagreements were settled by a third read against the codebook (Tie-break note column on Reviews).
B22: Disagreements settled | E22: =E4-E5 -> 8

Sheet Codebook
B1: Codebook
B2: One primary driver per review: the reason that customer would contact support.
B4: Key | C4: Driver | D4: What counts | E4: Subtags
B5: partner_cancellation | C5: No-shows & cancellations | D5: The professional didn't turn up, cancelled late, or the company kept rescheduling or had no one to send | E5: Cancelled at the last minute, No professional available, Didn't show up, Rescheduled again and again
B6: service_quality | C6: Service quality & conduct | D6: Poor skill, rushed or incomplete work, hygiene, burns or rashes from technique, rude behaviour, safety | E6: Hygiene, Poor skill, Rude behaviour, Rushed or incomplete, Safety, privacy or theft, Burn, cut or rash
B7: price_clarity | C7: Price & offer clarity | D7: Price or offer not as shown: extra charges at checkout, coupons or free-service offers that don't work | E7: Extra charges at checkout, Membership or package confusion, Offer or coupon not honoured, Price different from shown
B8: payment_refund | C8: Payments & refunds | D8: Money taken or stuck: refund slow or refused, charged but not served, wallet or coupon money lost | E8: Charged, not served, Refund delayed, Refund refused, Wallet or coupon money lost
B9: support | C9: Support itself | D9: Complaint is only about support: unreachable, scripted, slow, no escalation | E9: Slow resolution, Scripted, unhelpful replies, Can't reach support
B10: app | C10: App & booking bugs | D10: App crashes or won't open, login, booking or checkout bugs, no slots, spam notifications | E10: Booking or checkout bug, Crashes or won't open, Login or OTP, Other app issue, No slots
B11: delay | C11: Late arrivals | D11: Professional arrived late, assignment took long, or the service overran | E11: Arrived late
B12: product_fit | C12: Products used | D12: Product quality, missing or wrong products, pushed upsells, reactions blamed on the product | E12: Missing or wrong products, Product quality, Reaction to a product, Pushed product upsell
B13: other | C13: Other or vague | D13: A complaint with no specific problem, e.g. 'worst app', 'scam' | E13: Other issue, Too vague to classify
B14: praise | C14: Praise | D14: Positive review with no complaint | E14: Praised the professional, Praised the service, Praised the value
B16: Rule 1: support is the driver only when support itself is the whole complaint; otherwise the underlying problem is the driver and support is secondary.
B17: Rule 2: a burn or rash blamed on technique is Service quality; blamed on the product is Products used.
B18: Rule 3: vanishing offers, unusable coupons and fake promo notifications are Price & offer clarity.
B19: Rule 4: a mixed review counts its complaint. A vague 'worst app' with no detail is Other.

Sheet JD Map
B1: Built for this role
B2: Each JD line, where it is in this teardown, and where I've done it before.
B4: The JD asks for | C4: In this teardown | D4: Where I've done it before
B5: Root cause analysis | C5: Five whys on each top driver, with evidence vs hypothesis marked and a test that would prove each one wrong | D5: LVX: funnel analysis across ₹3.5 Cr, ₹7 Cr and ₹9 Cr+ launches; found where investors stalled; conversion up 20%
B6: Complaint reduction | C6: Three fixes with an owner, one metric, a target and a pilot design | D6: Techvaraha: 4 SOPs, QA workflows and KRAs; on-time delivery from 65% to 90%; zero missed deliverables for 3 quarters
B7: Lower contact rates | C7: Contacts per 100 bookings as the one metric; an impact model in contacts and rupees | D7: Techvaraha: escalation turnaround down 40% with one tracker and a review rhythm
B8: Crisp narrative | C8: Five slides, three minutes, and a one-page readout: problem, root cause, impact, action | D8: Techvaraha: 15+ executive presentations
B9: Leadership presentations | C9: A readout written for a VP decision, with the bias said out loud | D9: LVX: dashboards for the founder and management tracking ₹7 Cr+ of pipeline; reporting accuracy up 30%
B10: Clean, trustworthy data | C10: Two independent taggers, agreement and kappa measured, names and IDs removed | D10: LVX: reporting SOPs and data workflows; manual errors down 35%
B11: Supply-side ops | C11: No-show root cause traced to slot inventory vs confirmed capacity | D11: Built a network of 1,400+ healthcare practitioners and 15+ hospital tie-ups

Sheet Reviews
A1: # | B1: Date | C1: Month | D1: Stars | E1: App version | F1: Title | G1: Review (names and IDs removed) | H1: Primary driver | I1: Subtag | J1: Also mentions | K1: Contacted support | L1: Support failed | M1: Severity | N1: Says they'll leave | O1: Service | P1: City | Q1: Amount ₹ | R1: Evidence quote | S1: Tagger A | T1: Tagger B | U1: Tie-break note
A2: 1 | B2: 46316 | C2: =TEXT(B2,"yyyy-mm") -> 2026-10 | D2: 1 | E2: 18.9.0 | F2: The most unprofessional service from a lady in Bangalore | G2: I got assigned a lady called [name] in Bangalore for my service. After I got undressed, she pointed her phone towards me for a picture . I was totally freaked out, I jumped out of the bed and she said she needs to upload pics for her company. Who takes pics after the person is undressed?? Even after that, she kept saying she’s connecting music etc.. I told her I will get into bed after she’s done with her work on the phone as I feel uncomfortable with a person having their phone while I’m undressed.. so she just said she doesn’t feel comfortable with me and is leaving. I had a really bad back ache and waited 45 mins for her to show up and she just cancelled . And the whole time I was soft spoken and polite with her, even the one second where the phone was pointed at me when she was taking my pic, I never helped I just jumped out of the camera frame. And just because I told her I want to get into bed after she’s finishes her phone stuff, she decided to leave They should really have a way to file a complaint against such bad conduct and remove these providers from the app. After she left, I called the people and they just rescheduled a service. However, the previous provider disappeared from my app and I couldn’t even give her a rating or file a complaint against her. This means that whatever she is up to, she can go from house to house with her phone, and if anyone objects, she can just say I’m uncomfortable working with you and leave. And the people who are oblivious get taken for a ride. Honestly, my whole body is shaking after this experience even as a write this review. Definitely not using this app ever again | H2: service_quality | I2: safety_or_theft | J2: partner_cancellation, delay, support | K2: yes | L2: yes | M2: high | N2: yes | O2: massage_spa | P2: Bangalore | Q2: 0 | R2: After I got undressed, she pointed her phone towards me for a picture . I was totally freaked out | S2: service_quality | T2: service_quality
A3: 2 | B3: 46315 | C3: =TEXT(B3,"yyyy-mm") -> 2026-10 | D3: 1 | E3: 18.9.0 | F3: Worst experience | G3: I don’t want to blame the beautician personally, but my precious time was wasted on a festival day. She was clearly unskilled, and the waxing was done so poorly that my skin got hurt. I stopped the remaining services to avoid further damage. The worst part is that whatever happens to our skin, Yes Madam will simply ignore it, and customers are left to suffer and bear the consequences. They take no responsibility for the damage or discomfort caused. If they cannot ensure skilled professionals and proper service quality, they should not compromise with customers’ skin and safety. Very disappointing experience and a complete waste of time and money. | H3: service_quality | I3: skin_injury_or_reaction | K3: no | L3: no | M3: high | N3: no | O3: waxing | Q3: 0 | R3: She was clearly unskilled, and the waxing was done so poorly that my skin got hurt. | S3: service_quality | T3: service_quality
A4: 3 | B4: 46315 | C4: =TEXT(B4,"yyyy-mm") -> 2026-10 | D4: 5 | E4: 18.9.0 | F4: Good service | G4: It’s good | H4: praise | I4: praise_service | K4: no | L4: no | M4: none | N4: no | O4: unknown | Q4: 0 | R4: It’s good | S4: praise | T4: praise
A5: 4 | B5: 46315 | C5: =TEXT(B5,"yyyy-mm") -> 2026-10 | D5: 3 | E5: 18.9.0 | F5: Use better kit | G5: Experience would have been better if pedicure kit will have quality products | H5: product_fit | I5: product_quality | K5: no | L5: no | M5: low | N5: no | O5: mani_pedi | Q5: 0 | R5: Experience would have been better if pedicure kit will have quality products | S5: product_fit | T5: product_fit
A6: 5 | B6: 46315 | C6: =TEXT(B6,"yyyy-mm") -> 2026-10 | D6: 5 | E6: 18.9.0 | F6: Awesome Service | G6: Extremely convenient ! | H6: praise | I6: praise_service | K6: no | L6: no | M6: none | N6: no | O6: unknown | Q6: 0 | R6: Extremely convenient ! | S6: praise | T6: praise
A7: 6 | B7: 46315 | C7: =TEXT(B7,"yyyy-mm") -> 2026-10 | D7: 1 | E7: 18.9.0 | F7: Paid on 16th October but booking not done till now | G7: I’ve wasted so much time trying to get response but to no avail. Tel number is not working and help chat is disgustingly inefficient | H7: payment_refund | I7: charged_not_served | J7: support | K7: yes | L7: yes | M7: high | N7: no | O7: unknown | Q7: 0 | R7: Paid on 16th October but booking not done till now | S7: payment_refund | T7: payment_refund
A8: 7 | B8: 46315 | C8: =TEXT(B8,"yyyy-mm") -> 2026-10 | D8: 5 | E8: 18.9.0 | F8: Good to go with yes madam | G8: Very satisfying and comfortable service | H8: praise | I8: praise_service | K8: no | L8: no | M8: none | N8: no | O8: unknown | Q8: 0 | R8: Very satisfying and comfortable service | S8: praise | T8: praise
A9: 8 | B9: 46315 | C9: =TEXT(B9,"yyyy-mm") -> 2026-10 | D9: 1 | E9: 18.9.0 | F9: Money stollen by [name] professional | G9: Extremely disappointing experience with Yes Madam! The service was absolutely terrible, and the professional was rude and rushed the massage and pedicure. To make matters worse, our wallet was stolen during the visit, and despite raising this serious issue, Yes Madam has taken no proper action so far. This is completely unacceptable. Customer safety and accountability should be a priority. We paid for a service and ended up dealing with such a distressing experience. I would not recommend this app until they take responsibility and resolve this matter. Yes Madam, please take action and help us recover our stolen money. | H9: service_quality | I9: safety_or_theft | J9: support | K9: yes | L9: yes | M9: high | N9: no | O9: multiple | Q9: 0 | R9: our wallet was stolen during the visit, and despite raising this serious issue, Yes Madam has taken no proper action so far. | S9: service_quality | T9: service_quality
A10: 9 | B10: 46314 | C10: =TEXT(B10,"yyyy-mm") -> 2026-10 | D10: 1 | E10: 18.9.0 | F10: App crash not opening | G10: The app keeps crashing despite re-download it’s just not opening | H10: app | I10: crash_or_wont_open | K10: no | L10: no | M10: low | N10: no | O10: unknown | Q10: 0 | R10: The app keeps crashing despite re-download it’s just not opening | S10: app | T10: app
A11: 10 | B11: 46314 | C11: =TEXT(B11,"yyyy-mm") -> 2026-10 | D11: 2 | E11: 18.9.0 | F11: Hiddden charges | G11: Too many hidden charges are on every service. If I’m booking a spa for 970 it sums up to 1399 by the end of the payment . Not cool not impressive | H11: price_clarity | I11: hidden_charges | K11: no | L11: no | M11: low | N11: no | O11: massage_spa | Q11: 1399 | R11: If I’m booking a spa for 970 it sums up to 1399 by the end of the payment | S11: price_clarity | T11: price_clarity
A12: 11 | B12: 46314 | C12: =TEXT(B12,"yyyy-mm") -> 2026-10 | D12: 1 | E12: 18.9.0 | F12: Fake promo | G12: Do not download this app. They will send you fake notifications about you have coupon in your wallet but actually they dont give you any. it is a way for them to increase down and collect customer data. | H12: price_clarity | I12: offer_not_honoured | J12: app | K12: no | L12: no | M12: low | N12: no | O12: unknown | Q12: 0 | R12: They will send you fake notifications about you have coupon in your wallet but actually they dont give you any. | S12: price_clarity | T12: price_clarity
A13: 12 | B13: 46314 | C13: =TEXT(B13,"yyyy-mm") -> 2026-10 | D13: 5 | E13: 18.9.0 | F13: Excellent | G13: Excellent service with professional’ hygiene & cleanup after work | H13: praise | I13: praise_service | K13: no | L13: no | M13: none | N13: no | O13: unknown | Q13: 0 | R13: Excellent service with professional’ hygiene & cleanup after work | S13: praise | T13: praise
A14: 13 | B14: 46314 | C14: =TEXT(B14,"yyyy-mm") -> 2026-10 | D14: 1 | E14: 18.9.0 | F14: Third class company | G14: Worst ever app I have seen | H14: other | I14: unclear | K14: no | L14: no | M14: low | N14: no | O14: unknown | Q14: 0 | R14: Worst ever app I have seen | S14: other | T14: other
A15: 14 | B15: 46313 | C15: =TEXT(B15,"yyyy-mm") -> 2026-10 | D15: 5 | E15: 18.9.0 | F15: [name] Yes Madam | G15: Amazing behaviour and service with additional massage also given complimentary! , strongly recommend her ! | H15: praise | I15: praise_professional | K15: no | L15: no | M15: none | N15: no | O15: massage_spa | Q15: 0 | R15: Amazing behaviour and service with additional massage also given complimentary! , strongly recommend her ! | S15: praise | T15: praise
A16: 15 | B16: 46313 | C16: =TEXT(B16,"yyyy-mm") -> 2026-10 | D16: 1 | E16: 18.9.0 | F16: Cancel my booking at the end moment | G16: Very Disappointing Service – Poor Customer Experience This was my first time booking a service through this app, and unfortunately, it was a very disappointing experience. My appointment was scheduled for 5:30 PM, and I waited the entire day for the service. However, at 5:40 PM, after the scheduled appointment time, I received a call from the executive informing me that my service had been cancelled. This is highly unprofessional and unacceptable. If the service was going to be cancelled, the company should have informed me well in advance instead of wasting my entire day. There is no respect for the customer’s time or commitment. My first experience with this app has been extremely disappointing. I would not recommend this service unless the company improves its booking system, communication, and customer service. | H16: partner_cancellation | I16: last_minute_cancel | K16: no | L16: no | M16: medium | N16: no | O16: unknown | Q16: 0 | R16: at 5:40 PM, after the scheduled appointment time, I received a call from the executive informing me that my service had been cancelled. | S16: partner_cancellation | T16: partner_cancellation
A17: 16 | B17: 46313 | C17: =TEXT(B17,"yyyy-mm") -> 2026-10 | D17: 5 | E17: 18.9.0 | F17: Spa | G17: 👌Nice experience | H17: praise | I17: praise_service | K17: no | L17: no | M17: none | N17: no | O17: massage_spa | Q17: 0 | R17: 👌Nice experience | S17: praise | T17: praise
A18: 17 | B18: 46313 | C18: =TEXT(B18,"yyyy-mm") -> 2026-10 | D18: 5 | E18: 18.9.0 | F18: [name] | G18: Very good person, [name] thnx u | H18: praise | I18: praise_professional | K18: no | L18: no | M18: none | N18: no | O18: unknown | Q18: 0 | R18: Very good person, [name] thnx u | S18: praise | T18: praise
A19: 18 | B19: 46313 | C19: =TEXT(B19,"yyyy-mm") -> 2026-10 | D19: 1 | E19: 18.9.0 | F19: Worst customer care service | G19: Very pathetic experience with laser treatment, they don’t give refunds on time, will be filing case in consumer court on this pathetic app, quality of services are pathetic | H19: payment_refund | I19: refund_delayed | J19: support, service_quality | K19: yes | L19: yes | M19: high | N19: no | O19: laser_advanced | Q19: 0 | R19: Very pathetic experience with laser treatment, they don’t give refunds on time, will be filing case in consumer court | S19: payment_refund | T19: payment_refund
A20: 19 | B20: 46313 | C20: =TEXT(B20,"yyyy-mm") -> 2026-10 | D20: 1 | E20: 18.9.0 | F20: App crashes on IPhone | G20: The app crashes on my iPhone not sure why it was working before | H20: app | I20: crash_or_wont_open | K20: no | L20: no | M20: low | N20: no | O20: unknown | Q20: 0 | R20: The app crashes on my iPhone not sure why it was working before | S20: app | T20: app
A21: 20 | B21: 46312 | C21: =TEXT(B21,"yyyy-mm") -> 2026-10 | D21: 5 | E21: 18.9.0 | F21: satisfied | G21: Very good | H21: praise | I21: praise_service | K21: no | L21: no | M21: none | N21: no | O21: unknown | Q21: 0 | R21: Very good | S21: praise | T21: praise
A22: 21 | B22: 46312 | C22: =TEXT(B22,"yyyy-mm") -> 2026-10 | D22: 2 | E22: 18.9.0 | F22: App is freezing unable to open App | G22: I have 1000₹ coupon and free service of pedicure, unable to access through website or app. Need urgent help. | H22: app | I22: crash_or_wont_open | J22: price_clarity | K22: no | L22: no | M22: low | N22: no | O22: mani_pedi | Q22: 1000 | R22: I have 1000₹ coupon and free service of pedicure, unable to access through website or app. | S22: app | T22: app
A23: 22 | B23: 46312 | C23: =TEXT(B23,"yyyy-mm") -> 2026-10 | D23: 1 | E23: 18.9.0 | F23: Horrible service | G23: They keep on rescheduling the appointment cant appoint a professional if one not available. They want their customer to suffer or compromise rather than providing solution themselves. | H23: partner_cancellation | I23: repeated_reschedule | K23: no | L23: no | M23: medium | N23: no | O23: unknown | Q23: 0 | R23: They keep on rescheduling the appointment cant appoint a professional if one not available. | S23: partner_cancellation | T23: partner_cancellation
A24: 23 | B24: 46312 | C24: =TEXT(B24,"yyyy-mm") -> 2026-10 | D24: 1 | E24: 18.9.0 | F24: Fake promises | G24: Fake claims for free pedicure. | H24: price_clarity | I24: offer_not_honoured | K24: no | L24: no | M24: low | N24: no | O24: mani_pedi | Q24: 0 | R24: Fake claims for free pedicure. | S24: price_clarity | T24: price_clarity
A25: 24 | B25: 46311 | C25: =TEXT(B25,"yyyy-mm") -> 2026-10 | D25: 5 | E25: 18.9.0 | F25: Facial Pedicure Threading | G25: The job was very good. Products used for facial and pedicure are very effective. Thank you Yes Madam ❤️ | H25: praise | I25: praise_service | K25: no | L25: no | M25: none | N25: no | O25: multiple | Q25: 0 | R25: The job was very good. Products used for facial and pedicure are very effective. | S25: praise | T25: praise
A26: 25 | B26: 46311 | C26: =TEXT(B26,"yyyy-mm") -> 2026-10 | D26: 1 | E26: 18.9.0 | F26: App is not opening | G26: App is not opening | H26: app | I26: crash_or_wont_open | K26: no | L26: no | M26: low | N26: no | O26: unknown | Q26: 0 | R26: App is not opening | S26: app | T26: app
A27: 26 | B27: 46311 | C27: =TEXT(B27,"yyyy-mm") -> 2026-10 | D27: 1 | E27: 18.9.0 | F27: Not reliable | G27: Not a great experience. Twice professionals didn’t show up. No cancellations, no notice, just plain didn’t show up. And everytime customer service had the same thing to say. « Sorry it won’t happen next time. » I don’t think the apps a good option if you have a fixed schedule or if your a working women. | H27: partner_cancellation | I27: no_show | J27: support | K27: yes | L27: yes | M27: medium | N27: no | O27: unknown | Q27: 0 | R27: Twice professionals didn’t show up. No cancellations, no notice, just plain didn’t show up. | S27: partner_cancellation | T27: partner_cancellation
A28: 27 | B28: 46311 | C28: =TEXT(B28,"yyyy-mm") -> 2026-10 | D28: 5 | E28: 18.9.0 | F28: Sweet and well spoken | G28: Gave a soothing massage | H28: praise | I28: praise_professional | K28: no | L28: no | M28: none | N28: no | O28: massage_spa | Q28: 0 | R28: Sweet and well spoken | Gave a soothing massage | S28: praise | T28: praise
A29: 28 | B29: 46311 | C29: =TEXT(B29,"yyyy-mm") -> 2026-10 | D29: 5 | E29: 18.9.0 | F29: Wow service | G29: Excellent with every penny | H29: praise | I29: praise_value | K29: no | L29: no | M29: none | N29: no | O29: unknown | Q29: 0 | R29: Excellent with every penny | S29: praise | T29: praise
A30: 29 | B30: 46311 | C30: =TEXT(B30,"yyyy-mm") -> 2026-10 | D30: 5 | E30: 18.9.0 | F30: A Big Thank You to [name] ❤ | G30: Had such a lovely experience with Yes Madam’s salon-at-home service! I truly enjoyed the whole experience. It’s always nice to have someone who makes you feel comfortable and takes care of you so well. Looking forward to booking again! | H30: praise | I30: praise_professional | K30: no | L30: no | M30: none | N30: no | O30: unknown | Q30: 0 | R30: Had such a lovely experience with Yes Madam’s salon-at-home service! I truly enjoyed the whole experience. | S30: praise | T30: praise
A31: 30 | B31: 46311 | C31: =TEXT(B31,"yyyy-mm") -> 2026-10 | D31: 1 | E31: 18.9.0 | F31: Fake Offers | G31: They are misleading customers with fake offers! They advertise a free pedicure offer starting at 1:00 PM, but by 1:01 PM, they claim the offer is already over. This is not the first time; they repeat the same thing every time. This feels like a complete scam and a way to fool customers. Very disappointing and unprofessional. Please stop making false promises just to attract customers! | H31: price_clarity | I31: offer_not_honoured | K31: no | L31: no | M31: low | N31: no | O31: mani_pedi | Q31: 0 | R31: They advertise a free pedicure offer starting at 1:00 PM, but by 1:01 PM, they claim the offer is already over. | S31: price_clarity | T31: price_clarity
A32: 31 | B32: 46310 | C32: =TEXT(B32,"yyyy-mm") -> 2026-10 | D32: 1 | E32: 18.9.0 | F32: Worst experience -My skin got worst | G32: My order id is - [id] I booked the korean waxing from yes madam after the procedure my skin started peeling , i got rashes all over my body and my skin started getting darker with the reactions , customer care team also not helping here , they dont accept the calls neither responding to me to solve my issue | H32: service_quality | I32: skin_injury_or_reaction | J32: support | K32: yes | L32: yes | M32: high | N32: no | O32: waxing | Q32: 0 | R32: I booked the korean waxing from yes madam after the procedure my skin started peeling , i got rashes all over my body | S32: service_quality | T32: service_quality
A33: 32 | B33: 46310 | C33: =TEXT(B33,"yyyy-mm") -> 2026-10 | D33: 4 | E33: 18.9.0 | F33: Korean mani pedi | G33: Plz increase the quantity of scrub … its too less for both hands and legs | H33: product_fit | I33: missing_or_wrong_products | K33: no | L33: no | M33: low | N33: no | O33: mani_pedi | Q33: 0 | R33: Plz increase the quantity of scrub … its too less for both hands and legs | S33: product_fit | T33: product_fit
A34: 33 | B34: 46310 | C34: =TEXT(B34,"yyyy-mm") -> 2026-10 | D34: 5 | E34: 18.9.0 | F34: Great | G34: Good service | H34: praise | I34: praise_service | K34: no | L34: no | M34: none | N34: no | O34: unknown | Q34: 0 | R34: Good service | S34: praise | T34: praise
A35: 34 | B35: 46310 | C35: =TEXT(B35,"yyyy-mm") -> 2026-10 | D35: 5 | E35: 18.9.0 | F35: . | G35: I had a wonderful experience with Yes Madam. [name] was very professional, polite, and friendly throughout the service. She did her work with great care and attention to detail, making sure I was comfortable and satisfied. I truly appreciate her dedication and excellent service. Thank you, [name], for making my experience so pleasant. I would definitely recommend Yes Madam to others! | H35: praise | I35: praise_professional | K35: no | L35: no | M35: none | N35: no | O35: unknown | Q35: 0 | R35: [name] was very professional, polite, and friendly throughout the service. | S35: praise | T35: praise
